[2024-06-22T19:46:59.870+0000] {local_task_job_runner.py:120} INFO - ::group::Pre task execution logs
[2024-06-22T19:46:59.880+0000] {taskinstance.py:2076} INFO - Dependencies all met for dep_context=non-requeueable deps ti=<TaskInstance: data_ingestion_gcs_dag.local_to_gcs_task manual__2024-06-22T19:36:37.099165+00:00 [queued]>
[2024-06-22T19:46:59.884+0000] {taskinstance.py:2076} INFO - Dependencies all met for dep_context=requeueable deps ti=<TaskInstance: data_ingestion_gcs_dag.local_to_gcs_task manual__2024-06-22T19:36:37.099165+00:00 [queued]>
[2024-06-22T19:46:59.884+0000] {taskinstance.py:2306} INFO - Starting attempt 2 of 2
[2024-06-22T19:46:59.890+0000] {taskinstance.py:2330} INFO - Executing <Task(PythonOperator): local_to_gcs_task> on 2024-06-22 19:36:37.099165+00:00
[2024-06-22T19:46:59.894+0000] {warnings.py:112} WARNING - /home/***/.local/lib/python3.12/site-packages/***/task/task_runner/standard_task_runner.py:61: DeprecationWarning: This process (pid=882) is multi-threaded, use of fork() may lead to deadlocks in the child.
  pid = os.fork()

[2024-06-22T19:46:59.895+0000] {standard_task_runner.py:63} INFO - Started process 891 to run task
[2024-06-22T19:46:59.895+0000] {standard_task_runner.py:90} INFO - Running: ['***', 'tasks', 'run', 'data_ingestion_gcs_dag', 'local_to_gcs_task', 'manual__2024-06-22T19:36:37.099165+00:00', '--job-id', '8', '--raw', '--subdir', 'DAGS_FOLDER/data_ingestion_gcs_dag.py', '--cfg-path', '/tmp/tmp72p0w6qg']
[2024-06-22T19:46:59.897+0000] {standard_task_runner.py:91} INFO - Job 8: Subtask local_to_gcs_task
[2024-06-22T19:46:59.935+0000] {task_command.py:426} INFO - Running <TaskInstance: data_ingestion_gcs_dag.local_to_gcs_task manual__2024-06-22T19:36:37.099165+00:00 [running]> on host c3c320ba30d6
[2024-06-22T19:46:59.980+0000] {taskinstance.py:2648} INFO - Exporting env vars: AIRFLOW_CTX_DAG_OWNER='***' AIRFLOW_CTX_DAG_ID='data_ingestion_gcs_dag' AIRFLOW_CTX_TASK_ID='local_to_gcs_task' AIRFLOW_CTX_EXECUTION_DATE='2024-06-22T19:36:37.099165+00:00' AIRFLOW_CTX_TRY_NUMBER='2' AIRFLOW_CTX_DAG_RUN_ID='manual__2024-06-22T19:36:37.099165+00:00'
[2024-06-22T19:46:59.981+0000] {taskinstance.py:430} INFO - ::endgroup::
[2024-06-22T19:47:02.997+0000] {_metadata.py:139} WARNING - Compute Engine Metadata server unavailable on attempt 1 of 3. Reason: timed out
[2024-06-22T19:47:03.007+0000] {_metadata.py:139} WARNING - Compute Engine Metadata server unavailable on attempt 2 of 3. Reason: [Errno 111] Connection refused
[2024-06-22T19:47:03.012+0000] {_metadata.py:139} WARNING - Compute Engine Metadata server unavailable on attempt 3 of 3. Reason: [Errno 111] Connection refused
[2024-06-22T19:47:03.016+0000] {_default.py:338} WARNING - Authentication failed using Compute Engine authentication due to unavailable metadata server.
[2024-06-22T19:47:03.017+0000] {taskinstance.py:441} INFO - ::group::Post task execution logs
[2024-06-22T19:47:03.021+0000] {taskinstance.py:2905} ERROR - Task failed with exception
Traceback (most recent call last):
  File "/home/airflow/.local/lib/python3.12/site-packages/airflow/models/taskinstance.py", line 465, in _execute_task
    result = _execute_callable(context=context, **execute_callable_kwargs)
             ^^^^^^^^^^^^^^^^^^^^^^^^^^^^^^^^^^^^^^^^^^^^^^^^^^^^^^^^^^^^^
  File "/home/airflow/.local/lib/python3.12/site-packages/airflow/models/taskinstance.py", line 432, in _execute_callable
    return execute_callable(context=context, **execute_callable_kwargs)
           ^^^^^^^^^^^^^^^^^^^^^^^^^^^^^^^^^^^^^^^^^^^^^^^^^^^^^^^^^^^^
  File "/home/airflow/.local/lib/python3.12/site-packages/airflow/models/baseoperator.py", line 401, in wrapper
    return func(self, *args, **kwargs)
           ^^^^^^^^^^^^^^^^^^^^^^^^^^^
  File "/home/airflow/.local/lib/python3.12/site-packages/airflow/operators/python.py", line 235, in execute
    return_value = self.execute_callable()
                   ^^^^^^^^^^^^^^^^^^^^^^^
  File "/home/airflow/.local/lib/python3.12/site-packages/airflow/operators/python.py", line 252, in execute_callable
    return self.python_callable(*self.op_args, **self.op_kwargs)
           ^^^^^^^^^^^^^^^^^^^^^^^^^^^^^^^^^^^^^^^^^^^^^^^^^^^^^
  File "/opt/airflow/dags/data_ingestion_gcs_dag.py", line 41, in upload_to_gcs
    client = storage.Client()
             ^^^^^^^^^^^^^^^^
  File "/home/airflow/.local/lib/python3.12/site-packages/google/cloud/storage/client.py", line 226, in __init__
    super(Client, self).__init__(
  File "/home/airflow/.local/lib/python3.12/site-packages/google/cloud/client/__init__.py", line 320, in __init__
    _ClientProjectMixin.__init__(self, project=project, credentials=credentials)
  File "/home/airflow/.local/lib/python3.12/site-packages/google/cloud/client/__init__.py", line 268, in __init__
    project = self._determine_default(project)
              ^^^^^^^^^^^^^^^^^^^^^^^^^^^^^^^^
  File "/home/airflow/.local/lib/python3.12/site-packages/google/cloud/client/__init__.py", line 287, in _determine_default
    return _determine_default_project(project)
           ^^^^^^^^^^^^^^^^^^^^^^^^^^^^^^^^^^^
  File "/home/airflow/.local/lib/python3.12/site-packages/google/cloud/_helpers/__init__.py", line 152, in _determine_default_project
    _, project = google.auth.default()
                 ^^^^^^^^^^^^^^^^^^^^^
  File "/home/airflow/.local/lib/python3.12/site-packages/google/auth/_default.py", line 691, in default
    raise exceptions.DefaultCredentialsError(_CLOUD_SDK_MISSING_CREDENTIALS)
google.auth.exceptions.DefaultCredentialsError: Your default credentials were not found. To set up Application Default Credentials, see https://cloud.google.com/docs/authentication/external/set-up-adc for more information.
[2024-06-22T19:47:03.065+0000] {taskinstance.py:1206} INFO - Marking task as FAILED. dag_id=data_ingestion_gcs_dag, task_id=local_to_gcs_task, run_id=manual__2024-06-22T19:36:37.099165+00:00, execution_date=20240622T193637, start_date=20240622T194659, end_date=20240622T194703
[2024-06-22T19:47:03.094+0000] {standard_task_runner.py:110} ERROR - Failed to execute job 8 for task local_to_gcs_task (Your default credentials were not found. To set up Application Default Credentials, see https://cloud.google.com/docs/authentication/external/set-up-adc for more information.; 891)
[2024-06-22T19:47:03.133+0000] {local_task_job_runner.py:240} INFO - Task exited with return code 1
[2024-06-22T19:47:03.155+0000] {taskinstance.py:3503} INFO - 0 downstream tasks scheduled from follow-on schedule check
[2024-06-22T19:47:03.158+0000] {local_task_job_runner.py:222} INFO - ::endgroup::
